Workbook
Name Slicer_Assignment_Group: #N/A
Name Slicer_Category: #N/A
Name Slicer_Created_Month: #N/A
Name Slicer_Priority: #N/A

Sheet Raw Data
A1: Ticket_ID | B1: Created_Date | C1: Resolved_Date | D1: Priority | E1: Status | F1: Category | G1: Assignment_Group | H1: Assigned_Agent | I1: Location | J1: Channel | K1: Impact | L1: Urgency
A2: TCK-1001 | B2: 45670 | C2: 45673 | D2: P4 | E2: Closed | F2: Password Reset | G2: Security | I2: Makati | J2: Chat | K2: Low | L2: Medium
A3: TCK-1002 | B3: 45661 | C3: 45665 | D3: P4 | E3: Closed | F3: Software Install | G3: Infrastructure | H3: Agent O | I3: Manila | J3: Portal | K3: Low | L3: Low
A4: TCK-1003 | B4: 45978 | C4: 45984 | D4: P1 | E4: Resolved | F4: Email Issue | G4: Network | H4: Agent G | I4: Davao | J4: Phone | K4: Low | L4: Low
A5: TCK-1004 | B5: 45843 | C5: 45843 | D5: P4 | E5: Resolved | F5: Login Issue | G5: Security | H5: Agent K | I5: Cebu | J5: Chat | K5: High | L5: Medium
A6: TCK-1005 | B6: 45894 | C6: 45902 | D6: P4 | E6: Resolved | F6: Access Request | G6: Applications | H6: Agent M | I6: Davao | J6: Portal | K6: Low | L6: High
A7: TCK-1006 | B7: 45945 | C7: 45952 | D7: P3 | E7: Closed | F7: Login Issue | G7: Network | H7: Agent D | I7: Iloilo | J7: Phone | K7: High | L7: Medium
A8: TCK-1007 | B8: 45716 | C8: 45716 | D8: P2 | E8: Closed | F8: Hardware Failure | G8: Applications | H8: Agent R | I8: Clark | J8: Chat | K8: Low | L8: High
A9: TCK-1008 | B9: 45934 | C9: 45935 | D9: P2 | E9: Resolved | F9: VPN Issue | G9: Service Desk | H9: Agent C | I9: Davao | J9: Phone | K9: High | L9: High
A10: TCK-1009 | B10: 45968 | C10: 45973 | D10: P4 | E10: In Progress | F10: Password Reset | G10: Security | H10: Agent H | I10: Makati | J10: Email | K10: High | L10: Low
A11: TCK-1010 | B11: 45688 | D11: P1 | E11: Resolved | F11: Software Install | G11: Network | H11: Agent I | I11: Cebu | J11: Email | K11: High | L11: Low
A12: TCK-1011 | B12: 45874 | C12: 45875 | D12: P4 | E12: Closed | F12: Login Issue | G12: Applications | H12: Agent R | I12: Makati | J12: Phone | K12: Medium | L12: High
A13: TCK-1012 | B13: 45665 | C13: 45665 | D13: P2 | E13: Closed | F13: Network Issue | G13: Service Desk | H13: Agent H | I13: Davao | J13: Email | K13: Low | L13: High
A14: TCK-1013 | B14: 45954 | C14: 45956 | D14: P1 | E14: Resolved | F14: VPN Issue | G14: Service Desk | I14: Manila | J14: Phone | K14: Low | L14: Medium
A15: TCK-1014 | B15: 45956 | C15: 45957 | D15: P2 | E15: Closed | F15: Login Issue | G15: Network | H15: Agent D | I15: BGC | J15: Portal | K15: Low | L15: High
A16: TCK-1015 | B16: 45836 | C16: 45839 | D16: P4 | E16: Closed | F16: VPN Issue | G16: Infrastructure | H16: Agent O | I16: Davao | J16: Email | K16: High | L16: High
A17: TCK-1016 | B17: 45762 | C17: 45768 | D17: P3 | E17: Closed | F17: Hardware Failure | G17: Infrastructure | H17: Agent H | I17: Iloilo | J17: Chat | K17: Low | L17: Low
A18: TCK-1017 | B18: 46011 | C18: 46020 | D18: P2 | E18: Closed | F18: VPN Issue | G18: Service Desk | H18: Agent B | I18: Makati | J18: Chat | K18: Medium | L18: Medium
A19: TCK-1018 | B19: 45779 | C19: 45780 | D19: P1 | E19: In Progress | F19: Hardware Failure | G19: Applications | H19: Agent R | I19: Manila | J19: Portal | K19: High | L19: Low
A20: TCK-1019 | B20: 45774 | D20: P2 | E20: Open | F20: Software Install | G20: Network | H20: Agent N | I20: BGC | J20: Chat | K20: High | L20: Low
A21: TCK-1020 | B21: 45793 | D21: P3 | E21: Resolved | F21: VPN Issue | G21: Applications | H21: Agent F | I21: Cebu | J21: Email | K21: Medium | L21: Medium
A22: TCK-1021 | B22: 45977 | C22: 45981 | D22: P2 | E22: Closed | F22: Network Issue | G22: Service Desk | H22: Agent H | I22: Iloilo | J22: Phone | K22: High | L22: High
A23: TCK-1022 | B23: 45954 | C23: 45957 | D23: P2 | E23: Closed | F23: VPN Issue | H23: Agent D | I23: Makati | J23: Chat | K23: High | L23: Low
A24: TCK-1023 | B24: 45901 | C24: 45904 | D24: P4 | E24: Resolved | F24: Access Request | G24: Security | H24: Agent F | I24: Cebu | J24: Portal | K24: High | L24: Low
A25: TCK-1024 | B25: 45720 | C25: 45727 | D25: P3 | E25: Resolved | F25: Software Install | G25: Network | H25: Agent C | I25: Davao | J25: Chat | K25: Medium | L25: High
A26: TCK-1025 | B26: 45924 | C26: 45925 | D26: P2 | E26: resolved | F26: Software Install | G26: Security | H26: Agent R | I26: Cebu | J26: Phone | K26: Medium | L26: Medium
A27: TCK-1026 | B27: 45873 | C27: 45874 | D27: P3 | E27: Resolved | F27: Login Issue | G27: Applications | H27: Agent O | I27: Cebu | J27: Portal | K27: High | L27: Medium
A28: TCK-1027 | B28: 45857 | C28: 45860 | D28: P2 | E28: RESOLVED | F28: Software Install | G28: Service Desk | H28: Agent G | I28: Makati | J28: Phone | K28: Medium | L28: Low
A29: TCK-1028 | B29: 45852 | C29: 45854 | D29: P2 | E29: Resolved | F29: Password Reset | G29: Infrastructure | H29: Agent M | I29: Manila | J29: Phone | K29: High | L29: Low
A30: TCK-1029 | B30: 45769 | C30: 45769 | D30: P4 | E30: Closed | F30: Software Install | G30: Applications | H30: Agent L | I30: Clark | J30: Phone | K30: Medium | L30: High
A31: TCK-1030 | B31: 46008 | C31: 46011 | D31: P4 | E31: Resolved | F31: Email Issue | G31: Applications | H31: Agent M | I31: Iloilo | J31: Portal | K31: High | L31: Medium
A32: TCK-1031 | B32: 45991 | C32: 45991 | D32: P2 | E32: Resolved | F32: VPN Issue | G32: Applications | H32: Agent A | I32: Cebu | J32: Phone | K32: Medium | L32: Low
A33: TCK-1032 | B33: 45790 | C33: 45793 | D33: P4 | E33: Resolved | F33: Hardware Failure | G33: Security | H33: Agent F | I33: BGC | J33: Portal | K33: High | L33: High
A34: TCK-1033 | B34: 45900 | C34: 45900 | D34: P4 | E34: IN PROGRESS | F34: Hardware Failure | G34: Applications | H34: Agent A | I34: Cebu | J34: Chat | K34: Medium | L34: High
A35: TCK-1034 | B35: 45842 | D35: P2 | E35: Closed | F35: Login Issue | G35: Network | H35: Agent N | I35: Iloilo | J35: Chat | K35: Medium | L35: Medium
A36: TCK-1035 | B36: 45787 | C36: 45790 | D36: P4 | E36: Closed | F36: Email Issue | G36: Security | H36: Agent A | I36: BGC | J36: Email | K36: High | L36: Medium
A37: TCK-1036 | B37: 45959 | C37: 45964 | D37: P3 | E37: Closed | F37: Email Issue | G37: Network | H37: Agent F | I37: Cebu | J37: Email | K37: Medium | L37: Low
A38: TCK-1037 | B38: 46017 | C38: 46018 | D38: P2 | E38: Closed | F38: Passwrod Reset | G38: Security | H38: Agent I | I38: Cebu | J38: Chat | K38: Medium | L38: High
A39: TCK-1038 | B39: 45864 | C39: 45865 | D39: P1 | E39: Closed | F39: Password Reset | G39: Applications | H39: Agent R | I39: BGC | J39: Portal | K39: Medium | L39: High
A40: TCK-1039 | B40: 45881 | C40: 45882 | D40: P4 | E40: Closed | F40: Software Install | G40: Infrastructure | H40: Agent J | I40: Manila | J40: Email | K40: Low | L40: Low
...

Sheet Cleaned
A1: Ticket_ID | B1: Created_Date | C1: Resolved_Date | D1: Priority | E1: Status | F1: Category | G1: Assignment_Group | H1: Assigned_Agent | I1: Location | J1: Channel | K1: Impact | L1: Urgency | M1: Resolution_Time (Days) | N1: SLA_Target(Days) | O1: SLA_Status | P1: Created_Month | Q1: Created_Year | R1: Open/Closed | S1: Resolution_Month
A2: TCK-1001 | B2: 45670 | C2: 45673 | D2: P4 | E2: Closed | F2: Password Reset | G2: Security | H2: Unassigned | I2: Makati | J2: Chat | K2: Low | L2: Medium | M2: =IF(C2="","",C2-B2) -> 3 | N2: =IF(D2="P1",1, IF(D2="P2",3, IF(D2="P3",5,7))) -> 7 | O2: =IF(C2="","Open", IF(M2<=N2, "Met", "Breached")) -> Met | P2: =TEXT(B2,"mmm") -> Jan | Q2: =YEAR(B2) -> 2025 | R2: =IF(C2="","Open","Closed") -> Closed | S2: =IF(C2="","Open",TEXT(C2,"mmm")) -> Jan
A3: TCK-1002 | B3: 45661 | C3: 45665 | D3: P4 | E3: Closed | F3: Software Install | G3: Infrastructure | H3: Agent O | I3: Manila | J3: Portal | K3: Low | L3: Low | M3: =IF(C3="","",C3-B3) -> 4 | N3: =IF(D3="P1",1, IF(D3="P2",3, IF(D3="P3",5,7))) -> 7 | O3: =IF(C3="","Open", IF(M3<=N3, "Met", "Breached")) -> Met | P3: =TEXT(B3,"mmm") -> Jan | Q3: =YEAR(B3) -> 2025 | R3: =IF(C3="","Open","Closed") -> Closed | S3: =IF(C3="","Open",TEXT(C3,"mmm")) -> Jan
A4: TCK-1002 | B4: 45978 | C4: 45984 | D4: P2 | E4: Closed | F4: Hardware Failure | G4: Security | H4: Agent K | I4: BGC | J4: Chat | K4: Medium | L4: High | M4: =IF(C4="","",C4-B4) -> 6 | N4: =IF(D4="P1",1, IF(D4="P2",3, IF(D4="P3",5,7))) -> 3 | O4: =IF(C4="","Open", IF(M4<=N4, "Met", "Breached")) -> Breached | P4: =TEXT(B4,"mmm") -> Nov | Q4: =YEAR(B4) -> 2025 | R4: =IF(C4="","Open","Closed") -> Closed | S4: =IF(C4="","Open",TEXT(C4,"mmm")) -> Nov
A5: TCK-1003 | B5: 45843 | C5: 45843 | D5: P1 | E5: Resolved | F5: Email Issue | G5: Network | H5: Agent G | I5: Davao | J5: Phone | K5: Low | L5: Low | M5: =IF(C5="","",C5-B5) -> 0 | N5: =IF(D5="P1",1, IF(D5="P2",3, IF(D5="P3",5,7))) -> 1 | O5: =IF(C5="","Open", IF(M5<=N5, "Met", "Breached")) -> Met | P5: =TEXT(B5,"mmm") -> Jul | Q5: =YEAR(B5) -> 2025 | R5: =IF(C5="","Open","Closed") -> Closed | S5: =IF(C5="","Open",TEXT(C5,"mmm")) -> Jul
A6: TCK-1004 | B6: 45894 | C6: 45902 | D6: P4 | E6: Resolved | F6: Login Issue | G6: Security | H6: Agent K | I6: Cebu | J6: Chat | K6: High | L6: Medium | M6: =IF(C6="","",C6-B6) -> 8 | N6: =IF(D6="P1",1, IF(D6="P2",3, IF(D6="P3",5,7))) -> 7 | O6: =IF(C6="","Open", IF(M6<=N6, "Met", "Breached")) -> Breached | P6: =TEXT(B6,"mmm") -> Aug | Q6: =YEAR(B6) -> 2025 | R6: =IF(C6="","Open","Closed") -> Closed | S6: =IF(C6="","Open",TEXT(C6,"mmm")) -> Sep
A7: TCK-1005 | B7: 45945 | C7: 45952 | D7: P4 | E7: Resolved | F7: Access Request | G7: Applications | H7: Agent M | I7: Davao | J7: Portal | K7: Low | L7: High | M7: =IF(C7="","",C7-B7) -> 7 | N7: =IF(D7="P1",1, IF(D7="P2",3, IF(D7="P3",5,7))) -> 7 | O7: =IF(C7="","Open", IF(M7<=N7, "Met", "Breached")) -> Met | P7: =TEXT(B7,"mmm") -> Oct | Q7: =YEAR(B7) -> 2025 | R7: =IF(C7="","Open","Closed") -> Closed | S7: =IF(C7="","Open",TEXT(C7,"mmm")) -> Oct
A8: TCK-1006 | B8: 45716 | C8: 45716 | D8: P3 | E8: Closed | F8: Login Issue | G8: Network | H8: Agent D | I8: Iloilo | J8: Phone | K8: High | L8: Medium | M8: =IF(C8="","",C8-B8) -> 0 | N8: =IF(D8="P1",1, IF(D8="P2",3, IF(D8="P3",5,7))) -> 5 | O8: =IF(C8="","Open", IF(M8<=N8, "Met", "Breached")) -> Met | P8: =TEXT(B8,"mmm") -> Feb | Q8: =YEAR(B8) -> 2025 | R8: =IF(C8="","Open","Closed") -> Closed | S8: =IF(C8="","Open",TEXT(C8,"mmm")) -> Feb
A9: TCK-1007 | B9: 45934 | C9: 45935 | D9: P2 | E9: Closed | F9: Hardware Failure | G9: Applications | H9: Agent R | I9: Clark | J9: Chat | K9: Low | L9: High | M9: =IF(C9="","",C9-B9) -> 1 | N9: =IF(D9="P1",1, IF(D9="P2",3, IF(D9="P3",5,7))) -> 3 | O9: =IF(C9="","Open", IF(M9<=N9, "Met", "Breached")) -> Met | P9: =TEXT(B9,"mmm") -> Oct | Q9: =YEAR(B9) -> 2025 | R9: =IF(C9="","Open","Closed") -> Closed | S9: =IF(C9="","Open",TEXT(C9,"mmm")) -> Oct
A10: TCK-1008 | B10: 45968 | C10: 45973 | D10: P2 | E10: Resolved | F10: Vpn Issue | G10: Service Desk | H10: Agent C | I10: Davao | J10: Phone | K10: High | L10: High | M10: =IF(C10="","",C10-B10) -> 5 | N10: =IF(D10="P1",1, IF(D10="P2",3, IF(D10="P3",5,7))) -> 3 | O10: =IF(C10="","Open", IF(M10<=N10, "Met", "Breached")) -> Breached | P10: =TEXT(B10,"mmm") -> Nov | Q10: =YEAR(B10) -> 2025 | R10: =IF(C10="","Open","Closed") -> Closed | S10: =IF(C10="","Open",TEXT(C10,"mmm")) -> Nov
A11: TCK-1009 | B11: 45688 | D11: P4 | E11: In Progress | F11: Password Reset | G11: Security | H11: Agent H | I11: Makati | J11: Email | K11: High | L11: Low | M11: =IF(C11="","",C11-B11) | N11: =IF(D11="P1",1, IF(D11="P2",3, IF(D11="P3",5,7))) -> 7 | O11: =IF(C11="","Open", IF(M11<=N11, "Met", "Breached")) -> Open | P11: =TEXT(B11,"mmm") -> Jan | Q11: =YEAR(B11) -> 2025 | R11: =IF(C11="","Open","Closed") -> Open | S11: =IF(C11="","Open",TEXT(C11,"mmm")) -> Open
A12: TCK-1010 | B12: 45874 | C12: 45875 | D12: P1 | E12: Resolved | F12: Software Install | G12: Network | H12: Agent I | I12: Cebu | J12: Email | K12: High | L12: Low | M12: =IF(C12="","",C12-B12) -> 1 | N12: =IF(D12="P1",1, IF(D12="P2",3, IF(D12="P3",5,7))) -> 1 | O12: =IF(C12="","Open", IF(M12<=N12, "Met", "Breached")) -> Met | P12: =TEXT(B12,"mmm") -> Aug | Q12: =YEAR(B12) -> 2025 | R12: =IF(C12="","Open","Closed") -> Closed | S12: =IF(C12="","Open",TEXT(C12,"mmm")) -> Aug
A13: TCK-1011 | B13: 45665 | C13: 45665 | D13: P4 | E13: Closed | F13: Login Issue | G13: Applications | H13: Agent R | I13: Makati | J13: Phone | K13: Medium | L13: High | M13: =IF(C13="","",C13-B13) -> 0 | N13: =IF(D13="P1",1, IF(D13="P2",3, IF(D13="P3",5,7))) -> 7 | O13: =IF(C13="","Open", IF(M13<=N13, "Met", "Breached")) -> Met | P13: =TEXT(B13,"mmm") -> Jan | Q13: =YEAR(B13) -> 2025 | R13: =IF(C13="","Open","Closed") -> Closed | S13: =IF(C13="","Open",TEXT(C13,"mmm")) -> Jan
A14: TCK-1012 | B14: 45954 | C14: 45956 | D14: P2 | E14: Closed | F14: Network Issue | G14: Service Desk | H14: Agent H | I14: Davao | J14: Email | K14: Low | L14: High | M14: =IF(C14="","",C14-B14) -> 2 | N14: =IF(D14="P1",1, IF(D14="P2",3, IF(D14="P3",5,7))) -> 3 | O14: =IF(C14="","Open", IF(M14<=N14, "Met", "Breached")) -> Met | P14: =TEXT(B14,"mmm") -> Oct | Q14: =YEAR(B14) -> 2025 | R14: =IF(C14="","Open","Closed") -> Closed | S14: =IF(C14="","Open",TEXT(C14,"mmm")) -> Oct
A15: TCK-1013 | B15: 45956 | C15: 45957 | D15: P1 | E15: Resolved | F15: Vpn Issue | G15: Service Desk | H15: Unassigned | I15: Manila | J15: Phone | K15: Low | L15: Medium | M15: =IF(C15="","",C15-B15) -> 1 | N15: =IF(D15="P1",1, IF(D15="P2",3, IF(D15="P3",5,7))) -> 1 | O15: =IF(C15="","Open", IF(M15<=N15, "Met", "Breached")) -> Met | P15: =TEXT(B15,"mmm") -> Oct | Q15: =YEAR(B15) -> 2025 | R15: =IF(C15="","Open","Closed") -> Closed | S15: =IF(C15="","Open",TEXT(C15,"mmm")) -> Oct
A16: TCK-1014 | B16: 45836 | C16: 45839 | D16: P2 | E16: Closed | F16: Login Issue | G16: Network | H16: Agent D | I16: BGC | J16: Portal | K16: Low | L16: High | M16: =IF(C16="","",C16-B16) -> 3 | N16: =IF(D16="P1",1, IF(D16="P2",3, IF(D16="P3",5,7))) -> 3 | O16: =IF(C16="","Open", IF(M16<=N16, "Met", "Breached")) -> Met | P16: =TEXT(B16,"mmm") -> Jun | Q16: =YEAR(B16) -> 2025 | R16: =IF(C16="","Open","Closed") -> Closed | S16: =IF(C16="","Open",TEXT(C16,"mmm")) -> Jul
A17: TCK-1015 | B17: 45762 | C17: 45768 | D17: P4 | E17: Closed | F17: Vpn Issue | G17: Infrastructure | H17: Agent O | I17: Davao | J17: Email | K17: High | L17: High | M17: =IF(C17="","",C17-B17) -> 6 | N17: =IF(D17="P1",1, IF(D17="P2",3, IF(D17="P3",5,7))) -> 7 | O17: =IF(C17="","Open", IF(M17<=N17, "Met", "Breached")) -> Met | P17: =TEXT(B17,"mmm") -> Apr | Q17: =YEAR(B17) -> 2025 | R17: =IF(C17="","Open","Closed") -> Closed | S17: =IF(C17="","Open",TEXT(C17,"mmm")) -> Apr
A18: TCK-1016 | B18: 46011 | C18: 46020 | D18: P3 | E18: Closed | F18: Hardware Failure | G18: Infrastructure | H18: Agent H | I18: Iloilo | J18: Chat | K18: Low | L18: Low | M18: =IF(C18="","",C18-B18) -> 9 | N18: =IF(D18="P1",1, IF(D18="P2",3, IF(D18="P3",5,7))) -> 5 | O18: =IF(C18="","Open", IF(M18<=N18, "Met", "Breached")) -> Breached | P18: =TEXT(B18,"mmm") -> Dec | Q18: =YEAR(B18) -> 2025 | R18: =IF(C18="","Open","Closed") -> Closed | S18: =IF(C18="","Open",TEXT(C18,"mmm")) -> Dec
A19: TCK-1017 | B19: 45779 | C19: 45780 | D19: P2 | E19: Closed | F19: Vpn Issue | G19: Service Desk | H19: Agent B | I19: Makati | J19: Chat | K19: Medium | L19: Medium | M19: =IF(C19="","",C19-B19) -> 1 | N19: =IF(D19="P1",1, IF(D19="P2",3, IF(D19="P3",5,7))) -> 3 | O19: =IF(C19="","Open", IF(M19<=N19, "Met", "Breached")) -> Met | P19: =TEXT(B19,"mmm") -> May | Q19: =YEAR(B19) -> 2025 | R19: =IF(C19="","Open","Closed") -> Closed | S19: =IF(C19="","Open",TEXT(C19,"mmm")) -> May
A20: TCK-1018 | B20: 45774 | D20: P1 | E20: In Progress | F20: Hardware Failure | G20: Applications | H20: Agent R | I20: Manila | J20: Portal | K20: High | L20: Low | M20: =IF(C20="","",C20-B20) | N20: =IF(D20="P1",1, IF(D20="P2",3, IF(D20="P3",5,7))) -> 1 | O20: =IF(C20="","Open", IF(M20<=N20, "Met", "Breached")) -> Open | P20: =TEXT(B20,"mmm") -> Apr | Q20: =YEAR(B20) -> 2025 | R20: =IF(C20="","Open","Closed") -> Open | S20: =IF(C20="","Open",TEXT(C20,"mmm")) -> Open
A21: TCK-1019 | B21: 45793 | D21: P2 | E21: Open | F21: Software Install | G21: Network | H21: Agent N | I21: BGC | J21: Chat | K21: High | L21: Low | M21: =IF(C21="","",C21-B21) | N21: =IF(D21="P1",1, IF(D21="P2",3, IF(D21="P3",5,7))) -> 3 | O21: =IF(C21="","Open", IF(M21<=N21, "Met", "Breached")) -> Open | P21: =TEXT(B21,"mmm") -> May | Q21: =YEAR(B21) -> 2025 | R21: =IF(C21="","Open","Closed") -> Open | S21: =IF(C21="","Open",TEXT(C21,"mmm")) -> Open
A22: TCK-1020 | B22: 45977 | C22: 45981 | D22: P3 | E22: Resolved | F22: Vpn Issue | G22: Applications | H22: Agent F | I22: Cebu | J22: Email | K22: Medium | L22: Medium | M22: =IF(C22="","",C22-B22) -> 4 | N22: =IF(D22="P1",1, IF(D22="P2",3, IF(D22="P3",5,7))) -> 5 | O22: =IF(C22="","Open", IF(M22<=N22, "Met", "Breached")) -> Met | P22: =TEXT(B22,"mmm") -> Nov | Q22: =YEAR(B22) -> 2025 | R22: =IF(C22="","Open","Closed") -> Closed | S22: =IF(C22="","Open",TEXT(C22,"mmm")) -> Nov
A23: TCK-1021 | B23: 45954 | C23: 45957 | D23: P2 | E23: Closed | F23: Network Issue | G23: Service Desk | H23: Agent H | I23: Iloilo | J23: Phone | K23: High | L23: High | M23: =IF(C23="","",C23-B23) -> 3 | N23: =IF(D23="P1",1, IF(D23="P2",3, IF(D23="P3",5,7))) -> 3 | O23: =IF(C23="","Open", IF(M23<=N23, "Met", "Breached")) -> Met | P23: =TEXT(B23,"mmm") -> Oct | Q23: =YEAR(B23) -> 2025 | R23: =IF(C23="","Open","Closed") -> Closed | S23: =IF(C23="","Open",TEXT(C23,"mmm")) -> Oct
A24: TCK-1022 | B24: 45901 | C24: 45904 | D24: P2 | E24: Closed | F24: Vpn Issue | G24: Unassigned | H24: Agent D | I24: Makati | J24: Chat | K24: High | L24: Low | M24: =IF(C24="","",C24-B24) -> 3 | N24: =IF(D24="P1",1, IF(D24="P2",3, IF(D24="P3",5,7))) -> 3 | O24: =IF(C24="","Open", IF(M24<=N24, "Met", "Breached")) -> Met | P24: =TEXT(B24,"mmm") -> Sep | Q24: =YEAR(B24) -> 2025 | R24: =IF(C24="","Open","Closed") -> Closed | S24: =IF(C24="","Open",TEXT(C24,"mmm")) -> Sep
A25: TCK-1023 | B25: 45720 | C25: 45727 | D25: P4 | E25: Resolved | F25: Access Request | G25: Security | H25: Agent F | I25: Cebu | J25: Portal | K25: High | L25: Low | M25: =IF(C25="","",C25-B25) -> 7 | N25: =IF(D25="P1",1, IF(D25="P2",3, IF(D25="P3",5,7))) -> 7 | O25: =IF(C25="","Open", IF(M25<=N25, "Met", "Breached")) -> Met | P25: =TEXT(B25,"mmm") -> Mar | Q25: =YEAR(B25) -> 2025 | R25: =IF(C25="","Open","Closed") -> Closed | S25: =IF(C25="","Open",TEXT(C25,"mmm")) -> Mar
A26: TCK-1024 | B26: 45924 | C26: 45925 | D26: P3 | E26: Resolved | F26: Software Install | G26: Network | H26: Agent C | I26: Davao | J26: Chat | K26: Medium | L26: High | M26: =IF(C26="","",C26-B26) -> 1 | N26: =IF(D26="P1",1, IF(D26="P2",3, IF(D26="P3",5,7))) -> 5 | O26: =IF(C26="","Open", IF(M26<=N26, "Met", "Breached")) -> Met | P26: =TEXT(B26,"mmm") -> Sep | Q26: =YEAR(B26) -> 2025 | R26: =IF(C26="","Open","Closed") -> Closed | S26: =IF(C26="","Open",TEXT(C26,"mmm")) -> Sep
A27: TCK-1025 | B27: 45873 | C27: 45874 | D27: P2 | E27: Resolved | F27: Software Install | G27: Security | H27: Agent R | I27: Cebu | J27: Phone | K27: Medium | L27: Medium | M27: =IF(C27="","",C27-B27) -> 1 | N27: =IF(D27="P1",1, IF(D27="P2",3, IF(D27="P3",5,7))) -> 3 | O27: =IF(C27="","Open", IF(M27<=N27, "Met", "Breached")) -> Met | P27: =TEXT(B27,"mmm") -> Aug | Q27: =YEAR(B27) -> 2025 | R27: =IF(C27="","Open","Closed") -> Closed | S27: =IF(C27="","Open",TEXT(C27,"mmm")) -> Aug
A28: TCK-1026 | B28: 45857 | C28: 45860 | D28: P3 | E28: Resolved | F28: Login Issue | G28: Applications | H28: Agent O | I28: Cebu | J28: Portal | K28: High | L28: Medium | M28: =IF(C28="","",C28-B28) -> 3 | N28: =IF(D28="P1",1, IF(D28="P2",3, IF(D28="P3",5,7))) -> 5 | O28: =IF(C28="","Open", IF(M28<=N28, "Met", "Breached")) -> Met | P28: =TEXT(B28,"mmm") -> Jul | Q28: =YEAR(B28) -> 2025 | R28: =IF(C28="","Open","Closed") -> Closed | S28: =IF(C28="","Open",TEXT(C28,"mmm")) -> Jul
A29: TCK-1027 | B29: 45852 | C29: 45854 | D29: P2 | E29: Resolved | F29: Software Install | G29: Service Desk | H29: Agent G | I29: Makati | J29: Phone | K29: Medium | L29: Low | M29: =IF(C29="","",C29-B29) -> 2 | N29: =IF(D29="P1",1, IF(D29="P2",3, IF(D29="P3",5,7))) -> 3 | O29: =IF(C29="","Open", IF(M29<=N29, "Met", "Breached")) -> Met | P29: =TEXT(B29,"mmm") -> Jul | Q29: =YEAR(B29) -> 2025 | R29: =IF(C29="","Open","Closed") -> Closed | S29: =IF(C29="","Open",TEXT(C29,"mmm")) -> Jul
A30: TCK-1028 | B30: 45769 | C30: 45769 | D30: P2 | E30: Resolved | F30: Password Reset | G30: Infrastructure | H30: Agent M | I30: Manila | J30: Phone | K30: High | L30: Low | M30: =IF(C30="","",C30-B30) -> 0 | N30: =IF(D30="P1",1, IF(D30="P2",3, IF(D30="P3",5,7))) -> 3 | O30: =IF(C30="","Open", IF(M30<=N30, "Met", "Breached")) -> Met | P30: =TEXT(B30,"mmm") -> Apr | Q30: =YEAR(B30) -> 2025 | R30: =IF(C30="","Open","Closed") -> Closed | S30: =IF(C30="","Open",TEXT(C30,"mmm")) -> Apr
A31: TCK-1029 | B31: 46008 | C31: 46011 | D31: P4 | E31: Closed | F31: Software Install | G31: Applications | H31: Agent L | I31: Clark | J31: Phone | K31: Medium | L31: High | M31: =IF(C31="","",C31-B31) -> 3 | N31: =IF(D31="P1",1, IF(D31="P2",3, IF(D31="P3",5,7))) -> 7 | O31: =IF(C31="","Open", IF(M31<=N31, "Met", "Breached")) -> Met | P31: =TEXT(B31,"mmm") -> Dec | Q31: =YEAR(B31) -> 2025 | R31: =IF(C31="","Open","Closed") -> Closed | S31: =IF(C31="","Open",TEXT(C31,"mmm")) -> Dec
A32: TCK-1030 | B32: 45991 | C32: 45991 | D32: P4 | E32: Resolved | F32: Email Issue | G32: Applications | H32: Agent M | I32: Iloilo | J32: Portal | K32: High | L32: Medium | M32: =IF(C32="","",C32-B32) -> 0 | N32: =IF(D32="P1",1, IF(D32="P2",3, IF(D32="P3",5,7))) -> 7 | O32: =IF(C32="","Open", IF(M32<=N32, "Met", "Breached")) -> Met | P32: =TEXT(B32,"mmm") -> Nov | Q32: =YEAR(B32) -> 2025 | R32: =IF(C32="","Open","Closed") -> Closed | S32: =IF(C32="","Open",TEXT(C32,"mmm")) -> Nov
A33: TCK-1031 | B33: 45790 | C33: 45793 | D33: P2 | E33: Resolved | F33: Vpn Issue | G33: Applications | H33: Agent A | I33: Cebu | J33: Phone | K33: Medium | L33: Low | M33: =IF(C33="","",C33-B33) -> 3 | N33: =IF(D33="P1",1, IF(D33="P2",3, IF(D33="P3",5,7))) -> 3 | O33: =IF(C33="","Open", IF(M33<=N33, "Met", "Breached")) -> Met | P33: =TEXT(B33,"mmm") -> May | Q33: =YEAR(B33) -> 2025 | R33: =IF(C33="","Open","Closed") -> Closed | S33: =IF(C33="","Open",TEXT(C33,"mmm")) -> May
A34: TCK-1032 | B34: 45900 | C34: 45900 | D34: P4 | E34: Resolved | F34: Hardware Failure | G34: Security | H34: Agent F | I34: BGC | J34: Portal | K34: High | L34: High | M34: =IF(C34="","",C34-B34) -> 0 | N34: =IF(D34="P1",1, IF(D34="P2",3, IF(D34="P3",5,7))) -> 7 | O34: =IF(C34="","Open", IF(M34<=N34, "Met", "Breached")) -> Met | P34: =TEXT(B34,"mmm") -> Aug | Q34: =YEAR(B34) -> 2025 | R34: =IF(C34="","Open","Closed") -> Closed | S34: =IF(C34="","Open",TEXT(C34,"mmm")) -> Aug
A35: TCK-1033 | B35: 45842 | D35: P4 | E35: In Progress | F35: Hardware Failure | G35: Applications | H35: Agent A | I35: Cebu | J35: Chat | K35: Medium | L35: High | M35: =IF(C35="","",C35-B35) | N35: =IF(D35="P1",1, IF(D35="P2",3, IF(D35="P3",5,7))) -> 7 | O35: =IF(C35="","Open", IF(M35<=N35, "Met", "Breached")) -> Open | P35: =TEXT(B35,"mmm") -> Jul | Q35: =YEAR(B35) -> 2025 | R35: =IF(C35="","Open","Closed") -> Open | S35: =IF(C35="","Open",TEXT(C35,"mmm")) -> Open
A36: TCK-1034 | B36: 45787 | C36: 45790 | D36: P2 | E36: Closed | F36: Login Issue | G36: Network | H36: Agent N | I36: Iloilo | J36: Chat | K36: Medium | L36: Medium | M36: =IF(C36="","",C36-B36) -> 3 | N36: =IF(D36="P1",1, IF(D36="P2",3, IF(D36="P3",5,7))) -> 3 | O36: =IF(C36="","Open", IF(M36<=N36, "Met", "Breached")) -> Met | P36: =TEXT(B36,"mmm") -> May | Q36: =YEAR(B36) -> 2025 | R36: =IF(C36="","Open","Closed") -> Closed | S36: =IF(C36="","Open",TEXT(C36,"mmm")) -> May
A37: TCK-1035 | B37: 45959 | C37: 45964 | D37: P4 | E37: Closed | F37: Email Issue | G37: Security | H37: Agent A | I37: BGC | J37: Email | K37: High | L37: Medium | M37: =IF(C37="","",C37-B37) -> 5 | N37: =IF(D37="P1",1, IF(D37="P2",3, IF(D37="P3",5,7))) -> 7 | O37: =IF(C37="","Open", IF(M37<=N37, "Met", "Breached")) -> Met | P37: =TEXT(B37,"mmm") -> Oct | Q37: =YEAR(B37) -> 2025 | R37: =IF(C37="","Open","Closed") -> Closed | S37: =IF(C37="","Open",TEXT(C37,"mmm")) -> Nov
A38: TCK-1036 | B38: 46017 | C38: 46018 | D38: P3 | E38: Closed | F38: Email Issue | G38: Network | H38: Agent F | I38: Cebu | J38: Email | K38: Medium | L38: Low | M38: =IF(C38="","",C38-B38) -> 1 | N38: =IF(D38="P1",1, IF(D38="P2",3, IF(D38="P3",5,7))) -> 5 | O38: =IF(C38="","Open", IF(M38<=N38, "Met", "Breached")) -> Met | P38: =TEXT(B38,"mmm") -> Dec | Q38: =YEAR(B38) -> 2025 | R38: =IF(C38="","Open","Closed") -> Closed | S38: =IF(C38="","Open",TEXT(C38,"mmm")) -> Dec
A39: TCK-1037 | B39: 45864 | C39: 45865 | D39: P2 | E39: Closed | F39: Password Reset | G39: Security | H39: Agent I | I39: Cebu | J39: Chat | K39: Medium | L39: High | M39: =IF(C39="","",C39-B39) -> 1 | N39: =IF(D39="P1",1, IF(D39="P2",3, IF(D39="P3",5,7))) -> 3 | O39: =IF(C39="","Open", IF(M39<=N39, "Met", "Breached")) -> Met | P39: =TEXT(B39,"mmm") -> Jul | Q39: =YEAR(B39) -> 2025 | R39: =IF(C39="","Open","Closed") -> Closed | S39: =IF(C39="","Open",TEXT(C39,"mmm")) -> Jul
A40: TCK-1038 | B40: 45881 | C40: 45882 | D40: P1 | E40: Closed | F40: Password Reset | G40: Applications | H40: Agent R | I40: BGC | J40: Portal | K40: Medium | L40: High | M40: =IF(C40="","",C40-B40) -> 1 | N40: =IF(D40="P1",1, IF(D40="P2",3, IF(D40="P3",5,7))) -> 1 | O40: =IF(C40="","Open", IF(M40<=N40, "Met", "Breached")) -> Met | P40: =TEXT(B40,"mmm") -> Aug | Q40: =YEAR(B40) -> 2025 | R40: =IF(C40="","Open","Closed") -> Closed | S40: =IF(C40="","Open",TEXT(C40,"mmm")) -> Aug
...

Sheet Pivot Tables
B2: Pivot Table 1 – Ticket Volume by Priority | F2: Pivot Table 2 – Open vs. Closed Tickets | J2: Pivot Table 3 – Tickets by Category | N2: Pivot Table 4 – Tickets by Assignment Group
B3: Row Labels | C3: Count of Ticket_ID | F3: Row Labels | G3: Count of Ticket_ID | J3: Row Labels | K3: Count of Ticket_ID | N3: Row Labels | O3: Count of Ticket_ID
B4: P4 | C4: 120 | F4: Closed | G4: 362 | J4: Vpn Issue | K4: 70 | N4: Infrastructure | O4: 112
B5: P3 | C5: 121 | F5: Open | G5: 138 | J5: Password Reset | K5: 68 | N5: Service Desk | O5: 101
B6: P2 | C6: 143 | F6: Grand Total | G6: 500 | J6: Access Request | K6: 66 | N6: Security | O6: 94
B7: P1 | C7: 116 | J7: Email Issue | K7: 66 | N7: Applications | O7: 92
B8: Grand Total | C8: 500 | J8: Login Issue | K8: 61 | N8: Network | O8: 89
J9: Software Install | K9: 59 | N9: Unassigned | O9: 12
J10: Network Issue | K10: 57 | N10: Grand Total | O10: 500
J11: Hardware Failure | K11: 53
B12: Pivot Table 5 – SLA Performance | J12: Grand Total | K12: 500
B13: Row Labels | C13: Count of Ticket_ID
B14: Breached | C14: 44
B15: Met | C15: 318
B16: Open | C16: 138 | F16: Pivot Table 6 – Monthly Ticket Trend | J16: Pivot Table 7 – Average Resolution Time
B17: Grand Total | C17: 500 | F17: Row Labels | G17: Count of Ticket_ID | J17: Row Labels | K17: Average of Resolution_Time (Days)
F18: Jan | G18: 46 | J18: P1 | K18: 1.1829268
F19: Feb | G19: 43 | J19: P2 | K19: 2.1132075
F20: Mar | G20: 44 | J20: P3 | K20: 2.7738095
F21: Apr | G21: 25 | J21: P4 | K21: 3.9340659
F22: May | G22: 36 | J22: Grand Total | K22: 2.5123967
F23: Jun | G23: 36
F24: Jul | G24: 35
F25: Aug | G25: 50
F26: Sep | G26: 49
F27: Oct | G27: 47
F28: Nov | G28: 43
F29: Dec | G29: 46
F30: Grand Total | G30: 500

Sheet Dashboard
A1: IT Service Desk Performance Dashboard
B2: Reporting Period: January 2025 – December 2025 | J2: Met Count | K2: Breached Count
J3: ='Pivot Tables'!C15 -> 318 | K3: ='Pivot Tables'!C14 -> 44
G7: Total Tickets | H7: Open Tickets | I7: Closed tickets | J7: SLA Compliance (%) | K7: Avg Resolution Time
G8: ='Pivot Tables'!C8 -> 500 | H8: ='Pivot Tables'!G5 -> 138 | I8: ='Pivot Tables'!G4 -> 362 | J8: =J3/(J3+K3) -> 0.87845304 | K8: =(GETPIVOTDATA("Resolution_Time (Days)",'Pivot Tables'!$J$17)) -> 2.5123967

Sheet Cleaning Data
A1: Data Cleaning Process
A3: 1. Converted the Created Date and Resolved Date columns to a consistent date format (yyyy-mm-dd)
A5: 2. Validated the Resolved Date column:
A6: A blank Resolved Date is acceptable if the ticket status is Open or In Progress.
A8: If the status is Resolved or Closed but the Resolved Date is blank, the record is considered invalid.
A10: 3. Standardized text formatting by applying the TRIM() and PROPER() functions to columns E–L, except for Column I, since it contains acronym values that should remain unchanged.
A12: 4. Replaced missing values in the Assigned Agent and Assignment Group column with "Unassigned".
A14: 5. Corrected the misspelled category "Passwrod Reset" to "Password Reset" to ensure consistent category names.

Sheet Insights
A3: Key Insights
A5: 1. VPN Issue was the most common type of support request in the dataset.
A6: 2. The Service Desk handled the largest share of tickets compared to the other assignment groups.
A7: 3. About 86% of resolved tickets met the required SLA, while the rest were resolved beyond the target time.
A8: 4. On average, P1 and P2 tickets were resolved faster than P3 and P4 tickets, showing that higher-priority issues were handled first.
A9: 5. Monthly ticket counts remained relatively stable, with a slight increase during the middle of the year before declining toward the end of the reporting period.
